<?xml version="1.0"?>
<robot name="my_robot">

  <link name="base">
    <visual>
        <origin xyz="0 0 0" rpy = "0 0 0"/>
        <geometry>
            <mesh filename="package://robotv1_description/meshes/base.stl"/>
        </geometry>
        <material name="blue">
            <color rgba="0.0 0.0 1.0 1.0"/>
        </material>
    
    </visual>

    <collision>
    
        <origin xyz="0 0 0" rpy = "0 0 0"/>
        <geometry>
            <mesh filename="package://robotv1_description/meshes/base.stl"/>
        </geometry>

    </collision>

    <inertial>
        <origin xyz="0 0 0.025"/>
        <mass value="2"/>
        <inertia ixx="0.00282" ixy="0.0" ixz="0.0"
           iyy="0.00282" iyz="0.0" izz="0.00480"/>
    </inertial>
  </link>

  <link name="base_link">
    <visual>
        <origin xyz="0 0 0" rpy="0 0 0"/>
        <geometry>
            <mesh filename="package://robotv1_description/meshes/base_link.stl"/>
        </geometry>
        <material name="green">
            <color rgba="0.047 0.949 0.302 1.0"/>
        </material>
    </visual>

    <collision>
        <origin xyz="0 0 0" rpy="0 0 0"/>
        <geometry>
            <mesh filename="package://robotv1_description/meshes/base_link.stl"/>
        </geometry>
    </collision>

    <inertial>
        <origin xyz="0 0 0.075" rpy="0 0 0"/>
        <mass value="1"/>
        <inertia
    ixx="0.0014083"
    iyy="0.0014083"
    izz="0.0024"
    ixy="0.0"
    ixz="0.0"
    iyz="0.0"/>
    </inertial>

  </link>

    <joint name="base_to_base_link" type="continuous">
        <parent link="base"/>
        <child link="base_link"/>

        <origin xyz="0 0 0" rpy="0 0 0"/>

        <axis xyz="0 0 1"/>
        
    </joint>

    <link name="shoulder">
        <visual>
            <origin xyz="0 0 -0.115430" rpy="0 0 0"/>
            <geometry>
                <mesh filename="package://robotv1_description/meshes/rod_shaft.stl"/>
            </geometry>
            <material name="red">
                <color rgba="1.0 0.0 0.0 1.0"/>
            </material>
        </visual>
        <collision>
            <origin xyz ="0 0 -0.115430" rpy="0 0 0"/>
            <geometry>
                <mesh filename="package://robotv1_description/meshes/rod_shaft.stl"/>
            </geometry>
        </collision>
        <inertial>
            <orgin xyz="0 0 0" rpy="0 0.7173303 0"/>
            <mass value="0.5"/>
            <inertia
            ixx="0.0009875"
            iyy="0.0009875"
            izz="0.0001"
            ixy="0.0"
            ixz="0.0"
            iyz="0.0"/>
        </inertial>
    </link>

    <joint name="shouler_to_base" type="revolute">
        <parent link="base_link"/>
        <child link="shoulder"/>

        <origin xyz="0 0 0.115430"  rpy="0 0 0"/>
        <axis xyz="0 1 0"/>
        <limit lower="-2.424" upper="0.7173303" effort="5" velocity="1"/>
    </joint>

    <link name="radar_link">
        <visual>
            <origin xyz="-0.099733 0 -0.204287" rpy="0 0 0"/>
            <geometry>
                <mesh filename="package://robotv1_description/meshes/radar_link.stl"/>
            </geometry>
        </visual>
        <collision>
            <origin xyz="-0.099733 0 -0.204287" rpy="0 0 0"/>
            <geometry>
                <mesh filename="package://robotv1_description/meshes/radar_link.stl"/>
            </geometry>
        </collision>
        <inertial>
            <origin xyz="0 0 0" rpy = "0 0 0"/>
            <mass value="0.5"/>
             <inertia
                ixx="0.000166667"
                iyy="0.000166667"
                izz="0.0003"
                ixy="0.0"
                ixz="0.0"
                iyz="0.0"/>
        </inertial>
    </link>

    <joint name="radar_to_shoulder" type="revolute">
        <parent link="shoulder"/>
        <child link="radar_link"/>
        
        <origin xyz="0.099733 0 0.089263" rpy="0 0 0"/>
        <axis xyz="0 1 0"/>
        <limit lower="-1.57" upper="1.57" effort="5" velocity="1"/>
    </joint>
</robot>